<?xml version="1.0"?>
<robot name="simple_arm">

    <!-- Link Base (Fijo) -->
    <link name="base_link">
        <visual>
            <geometry>
                <box size="0.4 0.4 0.1"/>
            </geometry>
            <material name="gray">
                <color rgba="0.5 0.5 0.5 1"/>
            </material>
        </visual>

        <collision>
          <geometry>
              <box size="0.4 0.4 0.1"/>
          </geometry>
        </collision>

    </link>

    <!-- Link Vertical (Azul) -->
    <link name="body_link">
        <visual>
            <geometry>
                <box size="0.1 0.1 0.9"/>
            </geometry>
            <material name="blue">
                <color rgba="0 0 1 1"/>
            </material>
        </visual>

        <collision>
          <geometry>
              <box size="0.1 0.1 0.9"/>
          </geometry>
        </collision>
    </link>

    <!-- Link Horizontal Pequeño (Azul) -->
    <link name="top_link">
        <visual>
            <origin xyz="-0.25 0 0"/>
            <geometry>
                <box size="0.4 0.1 0.1"/>
            </geometry>
            <material name="blue">
                <color rgba="0 0 1 1"/>
            </material>
        </visual>

        <collision>
          <geometry>
              <box size="0.4 0.1 0.1"/>
          </geometry>
        </collision>
    </link>

    <!-- Joint Base a Vertical (Fijo) -->
    <joint name="base_to_body" type="fixed">
        <parent link="base_link"/>
        <child link="body_link"/>
        <origin xyz="0 0 0.5"/>
    </joint>

    <!-- Joint Vertical a Horizontal (Rotación en X) -->
    <joint name="body_to_top" type="revolute">
        <parent link="body_link"/>
        <child link="top_link"/>
        <axis xyz="0 0 1"/>
        <limit effort="10"/>
        <origin xyz="0 0 0.45"/>
    </joint>

</robot>